2018-Mar-28 18:58:42 proxyDBManager.py[line:71]/ERROR/  ===== 创建数据库 proxy 表出现异常 =====
 (1064, "You have an error in your SQL syntax; check the manual that corresponds to your MySQL server version for the right syntax to use near 'CREATE TABLE proxy (\n              id INT(9) NOT NULL AUTO_INCREMENT PRIMARY KEY' at line 2")
Traceback (most recent call last):
  File "C:\Users\Cheney and Bean\Desktop\Go\mysite\to_travel_here\TravelSpider\proxyPool\dbManager\proxyDBManager.py", line 66, in create_proxy_table
    self.cursor.execute(createTableSql)
  File "C:\Python\lib\site-packages\pymysql\cursors.py", line 165, in execute
    result = self._query(query)
  File "C:\Python\lib\site-packages\pymysql\cursors.py", line 321, in _query
    conn.query(q)
  File "C:\Python\lib\site-packages\pymysql\connections.py", line 860, in query
    self._affected_rows = self._read_query_result(unbuffered=unbuffered)
  File "C:\Python\lib\site-packages\pymysql\connections.py", line 1061, in _read_query_result
    result.read()
  File "C:\Python\lib\site-packages\pymysql\connections.py", line 1349, in read
    first_packet = self.connection._read_packet()
  File "C:\Python\lib\site-packages\pymysql\connections.py", line 1018, in _read_packet
    packet.check_error()
  File "C:\Python\lib\site-packages\pymysql\connections.py", line 384, in check_error
    err.raise_mysql_exception(self._data)
  File "C:\Python\lib\site-packages\pymysql\err.py", line 107, in raise_mysql_exception
    raise errorclass(errno, errval)
pymysql.err.ProgrammingError: (1064, "You have an error in your SQL syntax; check the manual that corresponds to your MySQL server version for the right syntax to use near 'CREATE TABLE proxy (\n              id INT(9) NOT NULL AUTO_INCREMENT PRIMARY KEY' at line 2")
2018-Mar-28 18:58:42 retry.py[line:200]/DEBUG/  Converted retries value: 5 -> Retry(total=5, connect=None, read=None, redirect=None, status=None)
2018-Mar-28 18:58:42 retry.py[line:200]/DEBUG/  Converted retries value: 5 -> Retry(total=5, connect=None, read=None, redirect=None, status=None)
2018-Mar-28 18:58:42 connectionpool.py[line:208]/DEBUG/  Starting new HTTP connection (1): www.xicidaili.com
2018-Mar-28 18:58:42 connectionpool.py[line:396]/DEBUG/  http://www.xicidaili.com:80 "GET /wn/ HTTP/1.1" 200 None
2018-Mar-28 18:58:42 xiciSpider.py[line:74]/DEBUG/  list index out of range
2018-Mar-28 18:58:42 xiciSpider.py[line:74]/DEBUG/  list index out of range
2018-Mar-28 18:58:42 xiciSpider.py[line:74]/DEBUG/  list index out of range
2018-Mar-28 18:58:42 xiciSpider.py[line:74]/DEBUG/  list index out of range
2018-Mar-28 18:58:42 xiciSpider.py[line:76]/DEBUG/  抓取 xici 网站共计 46 个代理
2018-Mar-28 18:58:42 connectionpool.py[line:824]/DEBUG/  Starting new HTTPS connection (1): www.baidu.com
2018-Mar-28 18:58:43 connectionpool.py[line:396]/DEBUG/  https://www.baidu.com:443 "GET / HTTP/1.1" 200 None
2018-Mar-28 18:58:43 connectionpool.py[line:824]/DEBUG/  Starting new HTTPS connection (1): www.baidu.com
2018-Mar-28 18:58:43 connectionpool.py[line:396]/DEBUG/  https://www.baidu.com:443 "GET / HTTP/1.1" 200 None
2018-Mar-28 18:58:43 connectionpool.py[line:824]/DEBUG/  Starting new HTTPS connection (1): www.baidu.com
2018-Mar-28 18:58:43 connectionpool.py[line:396]/DEBUG/  https://www.baidu.com:443 "GET / HTTP/1.1" 200 None
2018-Mar-28 18:58:43 connectionpool.py[line:824]/DEBUG/  Starting new HTTPS connection (1): www.baidu.com
2018-Mar-28 18:58:43 connectionpool.py[line:396]/DEBUG/  https://www.baidu.com:443 "GET / HTTP/1.1" 200 None
2018-Mar-28 18:58:43 connectionpool.py[line:824]/DEBUG/  Starting new HTTPS connection (1): www.baidu.com
2018-Mar-28 18:58:44 connectionpool.py[line:396]/DEBUG/  https://www.baidu.com:443 "GET / HTTP/1.1" 200 None
2018-Mar-28 18:58:44 connectionpool.py[line:824]/DEBUG/  Starting new HTTPS connection (1): www.baidu.com
2018-Mar-28 18:58:44 connectionpool.py[line:396]/DEBUG/  https://www.baidu.com:443 "GET / HTTP/1.1" 200 None
2018-Mar-28 18:58:44 connectionpool.py[line:824]/DEBUG/  Starting new HTTPS connection (1): www.baidu.com
2018-Mar-28 18:58:44 connectionpool.py[line:396]/DEBUG/  https://www.baidu.com:443 "GET / HTTP/1.1" 200 None
2018-Mar-28 18:58:44 connectionpool.py[line:824]/DEBUG/  Starting new HTTPS connection (1): www.baidu.com
2018-Mar-28 18:58:45 connectionpool.py[line:396]/DEBUG/  https://www.baidu.com:443 "GET / HTTP/1.1" 200 None
2018-Mar-28 18:58:45 connectionpool.py[line:824]/DEBUG/  Starting new HTTPS connection (1): www.baidu.com
2018-Mar-28 18:58:45 connectionpool.py[line:396]/DEBUG/  https://www.baidu.com:443 "GET / HTTP/1.1" 200 None
2018-Mar-28 18:58:45 connectionpool.py[line:824]/DEBUG/  Starting new HTTPS connection (1): www.baidu.com
2018-Mar-28 18:58:45 connectionpool.py[line:396]/DEBUG/  https://www.baidu.com:443 "GET / HTTP/1.1" 200 None
2018-Mar-28 18:58:45 connectionpool.py[line:824]/DEBUG/  Starting new HTTPS connection (1): www.baidu.com
2018-Mar-28 18:58:45 connectionpool.py[line:396]/DEBUG/  https://www.baidu.com:443 "GET / HTTP/1.1" 200 None
2018-Mar-28 18:58:45 connectionpool.py[line:824]/DEBUG/  Starting new HTTPS connection (1): www.baidu.com
2018-Mar-28 18:58:46 connectionpool.py[line:396]/DEBUG/  https://www.baidu.com:443 "GET / HTTP/1.1" 200 None
2018-Mar-28 18:58:46 connectionpool.py[line:824]/DEBUG/  Starting new HTTPS connection (1): www.baidu.com
2018-Mar-28 18:58:46 connectionpool.py[line:396]/DEBUG/  https://www.baidu.com:443 "GET / HTTP/1.1" 200 None
2018-Mar-28 18:58:46 connectionpool.py[line:824]/DEBUG/  Starting new HTTPS connection (1): www.baidu.com
2018-Mar-28 18:58:46 connectionpool.py[line:396]/DEBUG/  https://www.baidu.com:443 "GET / HTTP/1.1" 200 None
2018-Mar-28 18:58:46 connectionpool.py[line:824]/DEBUG/  Starting new HTTPS connection (1): www.baidu.com
2018-Mar-28 18:58:47 connectionpool.py[line:396]/DEBUG/  https://www.baidu.com:443 "GET / HTTP/1.1" 200 None
2018-Mar-28 18:58:47 connectionpool.py[line:824]/DEBUG/  Starting new HTTPS connection (1): www.baidu.com
2018-Mar-28 18:58:47 connectionpool.py[line:396]/DEBUG/  https://www.baidu.com:443 "GET / HTTP/1.1" 200 None
2018-Mar-28 18:58:47 connectionpool.py[line:824]/DEBUG/  Starting new HTTPS connection (1): www.baidu.com
2018-Mar-28 18:58:47 connectionpool.py[line:396]/DEBUG/  https://www.baidu.com:443 "GET / HTTP/1.1" 200 None
2018-Mar-28 18:58:47 connectionpool.py[line:824]/DEBUG/  Starting new HTTPS connection (1): www.baidu.com
2018-Mar-28 18:58:47 connectionpool.py[line:396]/DEBUG/  https://www.baidu.com:443 "GET / HTTP/1.1" 200 None
2018-Mar-28 18:58:47 connectionpool.py[line:824]/DEBUG/  Starting new HTTPS connection (1): www.baidu.com
2018-Mar-28 18:58:48 connectionpool.py[line:396]/DEBUG/  https://www.baidu.com:443 "GET / HTTP/1.1" 200 None
2018-Mar-28 18:58:48 connectionpool.py[line:824]/DEBUG/  Starting new HTTPS connection (1): www.baidu.com
2018-Mar-28 18:58:48 connectionpool.py[line:396]/DEBUG/  https://www.baidu.com:443 "GET / HTTP/1.1" 200 None
2018-Mar-28 18:58:48 connectionpool.py[line:824]/DEBUG/  Starting new HTTPS connection (1): www.baidu.com
2018-Mar-28 18:58:48 connectionpool.py[line:396]/DEBUG/  https://www.baidu.com:443 "GET / HTTP/1.1" 200 None
2018-Mar-28 18:58:48 connectionpool.py[line:824]/DEBUG/  Starting new HTTPS connection (1): www.baidu.com
2018-Mar-28 18:58:49 connectionpool.py[line:396]/DEBUG/  https://www.baidu.com:443 "GET / HTTP/1.1" 200 None
2018-Mar-28 18:58:49 connectionpool.py[line:824]/DEBUG/  Starting new HTTPS connection (1): www.baidu.com
2018-Mar-28 18:58:49 connectionpool.py[line:396]/DEBUG/  https://www.baidu.com:443 "GET / HTTP/1.1" 200 None
2018-Mar-28 18:58:49 connectionpool.py[line:824]/DEBUG/  Starting new HTTPS connection (1): www.baidu.com
2018-Mar-28 18:58:49 connectionpool.py[line:396]/DEBUG/  https://www.baidu.com:443 "GET / HTTP/1.1" 200 None
2018-Mar-28 18:58:49 connectionpool.py[line:824]/DEBUG/  Starting new HTTPS connection (1): www.baidu.com
2018-Mar-28 18:58:49 connectionpool.py[line:396]/DEBUG/  https://www.baidu.com:443 "GET / HTTP/1.1" 200 None
2018-Mar-28 18:58:49 connectionpool.py[line:824]/DEBUG/  Starting new HTTPS connection (1): www.baidu.com
2018-Mar-28 18:58:50 connectionpool.py[line:396]/DEBUG/  https://www.baidu.com:443 "GET / HTTP/1.1" 200 None
2018-Mar-28 18:58:50 connectionpool.py[line:824]/DEBUG/  Starting new HTTPS connection (1): www.baidu.com
2018-Mar-28 18:58:50 connectionpool.py[line:396]/DEBUG/  https://www.baidu.com:443 "GET / HTTP/1.1" 200 None
2018-Mar-28 18:58:50 connectionpool.py[line:824]/DEBUG/  Starting new HTTPS connection (1): www.baidu.com
2018-Mar-28 18:58:50 connectionpool.py[line:396]/DEBUG/  https://www.baidu.com:443 "GET / HTTP/1.1" 200 None
2018-Mar-28 18:58:50 connectionpool.py[line:824]/DEBUG/  Starting new HTTPS connection (1): www.baidu.com
2018-Mar-28 18:58:50 connectionpool.py[line:396]/DEBUG/  https://www.baidu.com:443 "GET / HTTP/1.1" 200 None
2018-Mar-28 18:58:50 connectionpool.py[line:824]/DEBUG/  Starting new HTTPS connection (1): www.baidu.com
2018-Mar-28 18:58:51 connectionpool.py[line:396]/DEBUG/  https://www.baidu.com:443 "GET / HTTP/1.1" 200 None
2018-Mar-28 18:58:51 connectionpool.py[line:824]/DEBUG/  Starting new HTTPS connection (1): www.baidu.com
2018-Mar-28 18:58:51 connectionpool.py[line:396]/DEBUG/  https://www.baidu.com:443 "GET / HTTP/1.1" 200 None
2018-Mar-28 18:58:51 connectionpool.py[line:824]/DEBUG/  Starting new HTTPS connection (1): www.baidu.com
2018-Mar-28 18:58:51 connectionpool.py[line:396]/DEBUG/  https://www.baidu.com:443 "GET / HTTP/1.1" 200 None
2018-Mar-28 18:58:51 connectionpool.py[line:824]/DEBUG/  Starting new HTTPS connection (1): www.baidu.com
2018-Mar-28 18:58:52 connectionpool.py[line:396]/DEBUG/  https://www.baidu.com:443 "GET / HTTP/1.1" 200 None
2018-Mar-28 18:58:52 connectionpool.py[line:824]/DEBUG/  Starting new HTTPS connection (1): www.baidu.com
2018-Mar-28 18:58:52 connectionpool.py[line:396]/DEBUG/  https://www.baidu.com:443 "GET / HTTP/1.1" 200 None
2018-Mar-28 18:58:52 connectionpool.py[line:824]/DEBUG/  Starting new HTTPS connection (1): www.baidu.com
2018-Mar-28 18:58:52 connectionpool.py[line:396]/DEBUG/  https://www.baidu.com:443 "GET / HTTP/1.1" 200 None
2018-Mar-28 18:58:52 connectionpool.py[line:824]/DEBUG/  Starting new HTTPS connection (1): www.baidu.com
2018-Mar-28 18:58:52 connectionpool.py[line:396]/DEBUG/  https://www.baidu.com:443 "GET / HTTP/1.1" 200 None
2018-Mar-28 18:58:52 connectionpool.py[line:824]/DEBUG/  Starting new HTTPS connection (1): www.baidu.com
2018-Mar-28 18:58:53 connectionpool.py[line:396]/DEBUG/  https://www.baidu.com:443 "GET / HTTP/1.1" 200 None
2018-Mar-28 18:58:53 connectionpool.py[line:824]/DEBUG/  Starting new HTTPS connection (1): www.baidu.com
2018-Mar-28 18:58:53 connectionpool.py[line:396]/DEBUG/  https://www.baidu.com:443 "GET / HTTP/1.1" 200 None
2018-Mar-28 18:58:53 connectionpool.py[line:824]/DEBUG/  Starting new HTTPS connection (1): www.baidu.com
2018-Mar-28 18:58:53 connectionpool.py[line:396]/DEBUG/  https://www.baidu.com:443 "GET / HTTP/1.1" 200 None
2018-Mar-28 18:58:53 connectionpool.py[line:824]/DEBUG/  Starting new HTTPS connection (1): www.baidu.com
2018-Mar-28 18:58:54 connectionpool.py[line:396]/DEBUG/  https://www.baidu.com:443 "GET / HTTP/1.1" 200 None
2018-Mar-28 18:58:54 connectionpool.py[line:824]/DEBUG/  Starting new HTTPS connection (1): www.baidu.com
2018-Mar-28 18:58:54 connectionpool.py[line:396]/DEBUG/  https://www.baidu.com:443 "GET / HTTP/1.1" 200 None
2018-Mar-28 18:58:54 connectionpool.py[line:824]/DEBUG/  Starting new HTTPS connection (1): www.baidu.com
2018-Mar-28 18:58:54 connectionpool.py[line:396]/DEBUG/  https://www.baidu.com:443 "GET / HTTP/1.1" 200 None
2018-Mar-28 18:58:54 connectionpool.py[line:824]/DEBUG/  Starting new HTTPS connection (1): www.baidu.com
2018-Mar-28 18:58:54 connectionpool.py[line:396]/DEBUG/  https://www.baidu.com:443 "GET / HTTP/1.1" 200 None
2018-Mar-28 18:58:54 connectionpool.py[line:824]/DEBUG/  Starting new HTTPS connection (1): www.baidu.com
2018-Mar-28 18:58:55 connectionpool.py[line:396]/DEBUG/  https://www.baidu.com:443 "GET / HTTP/1.1" 200 None
2018-Mar-28 18:58:55 connectionpool.py[line:824]/DEBUG/  Starting new HTTPS connection (1): www.baidu.com
2018-Mar-28 18:58:55 connectionpool.py[line:396]/DEBUG/  https://www.baidu.com:443 "GET / HTTP/1.1" 200 None
2018-Mar-28 18:58:55 connectionpool.py[line:824]/DEBUG/  Starting new HTTPS connection (1): www.baidu.com
2018-Mar-28 18:58:55 connectionpool.py[line:396]/DEBUG/  https://www.baidu.com:443 "GET / HTTP/1.1" 200 None
2018-Mar-28 18:58:55 requestEnginer.py[line:67]/DEBUG/  =====  经过过滤后剩下 46 个代理  =====
2018-Mar-28 18:58:55 proxyDBManager.py[line:102]/ERROR/  ===== mysql insert_proxy exception =====
 (1146, "Table 'proxy.proxy' doesn't exist")
Traceback (most recent call last):
  File "C:\Users\Cheney and Bean\Desktop\Go\mysite\to_travel_here\TravelSpider\proxyPool\dbManager\proxyDBManager.py", line 97, in insert_proxy_table
    self.cursor.execute(insertSql, data)
  File "C:\Python\lib\site-packages\pymysql\cursors.py", line 165, in execute
    result = self._query(query)
  File "C:\Python\lib\site-packages\pymysql\cursors.py", line 321, in _query
    conn.query(q)
  File "C:\Python\lib\site-packages\pymysql\connections.py", line 860, in query
    self._affected_rows = self._read_query_result(unbuffered=unbuffered)
  File "C:\Python\lib\site-packages\pymysql\connections.py", line 1061, in _read_query_result
    result.read()
  File "C:\Python\lib\site-packages\pymysql\connections.py", line 1349, in read
    first_packet = self.connection._read_packet()
  File "C:\Python\lib\site-packages\pymysql\connections.py", line 1018, in _read_packet
    packet.check_error()
  File "C:\Python\lib\site-packages\pymysql\connections.py", line 384, in check_error
    err.raise_mysql_exception(self._data)
  File "C:\Python\lib\site-packages\pymysql\err.py", line 107, in raise_mysql_exception
    raise errorclass(errno, errval)
pymysql.err.ProgrammingError: (1146, "Table 'proxy.proxy' doesn't exist")
2018-Mar-28 18:58:55 proxyDBManager.py[line:102]/ERROR/  ===== mysql insert_proxy exception =====
 (1146, "Table 'proxy.proxy' doesn't exist")
Traceback (most recent call last):
  File "C:\Users\Cheney and Bean\Desktop\Go\mysite\to_travel_here\TravelSpider\proxyPool\dbManager\proxyDBManager.py", line 97, in insert_proxy_table
    self.cursor.execute(insertSql, data)
  File "C:\Python\lib\site-packages\pymysql\cursors.py", line 165, in execute
    result = self._query(query)
  File "C:\Python\lib\site-packages\pymysql\cursors.py", line 321, in _query
    conn.query(q)
  File "C:\Python\lib\site-packages\pymysql\connections.py", line 860, in query
    self._affected_rows = self._read_query_result(unbuffered=unbuffered)
  File "C:\Python\lib\site-packages\pymysql\connections.py", line 1061, in _read_query_result
    result.read()
  File "C:\Python\lib\site-packages\pymysql\connections.py", line 1349, in read
    first_packet = self.connection._read_packet()
  File "C:\Python\lib\site-packages\pymysql\connections.py", line 1018, in _read_packet
    packet.check_error()
  File "C:\Python\lib\site-packages\pymysql\connections.py", line 384, in check_error
    err.raise_mysql_exception(self._data)
  File "C:\Python\lib\site-packages\pymysql\err.py", line 107, in raise_mysql_exception
    raise errorclass(errno, errval)
pymysql.err.ProgrammingError: (1146, "Table 'proxy.proxy' doesn't exist")
2018-Mar-28 18:58:55 proxyDBManager.py[line:102]/ERROR/  ===== mysql insert_proxy exception =====
 (1146, "Table 'proxy.proxy' doesn't exist")
Traceback (most recent call last):
  File "C:\Users\Cheney and Bean\Desktop\Go\mysite\to_travel_here\TravelSpider\proxyPool\dbManager\proxyDBManager.py", line 97, in insert_proxy_table
    self.cursor.execute(insertSql, data)
  File "C:\Python\lib\site-packages\pymysql\cursors.py", line 165, in execute
    result = self._query(query)
  File "C:\Python\lib\site-packages\pymysql\cursors.py", line 321, in _query
    conn.query(q)
  File "C:\Python\lib\site-packages\pymysql\connections.py", line 860, in query
    self._affected_rows = self._read_query_result(unbuffered=unbuffered)
  File "C:\Python\lib\site-packages\pymysql\connections.py", line 1061, in _read_query_result
    result.read()
  File "C:\Python\lib\site-packages\pymysql\connections.py", line 1349, in read
    first_packet = self.connection._read_packet()
  File "C:\Python\lib\site-packages\pymysql\connections.py", line 1018, in _read_packet
    packet.check_error()
  File "C:\Python\lib\site-packages\pymysql\connections.py", line 384, in check_error
    err.raise_mysql_exception(self._data)
  File "C:\Python\lib\site-packages\pymysql\err.py", line 107, in raise_mysql_exception
    raise errorclass(errno, errval)
pymysql.err.ProgrammingError: (1146, "Table 'proxy.proxy' doesn't exist")
2018-Mar-28 18:58:55 proxyDBManager.py[line:102]/ERROR/  ===== mysql insert_proxy exception =====
 (1146, "Table 'proxy.proxy' doesn't exist")
Traceback (most recent call last):
  File "C:\Users\Cheney and Bean\Desktop\Go\mysite\to_travel_here\TravelSpider\proxyPool\dbManager\proxyDBManager.py", line 97, in insert_proxy_table
    self.cursor.execute(insertSql, data)
  File "C:\Python\lib\site-packages\pymysql\cursors.py", line 165, in execute
    result = self._query(query)
  File "C:\Python\lib\site-packages\pymysql\cursors.py", line 321, in _query
    conn.query(q)
  File "C:\Python\lib\site-packages\pymysql\connections.py", line 860, in query
    self._affected_rows = self._read_query_result(unbuffered=unbuffered)
  File "C:\Python\lib\site-packages\pymysql\connections.py", line 1061, in _read_query_result
    result.read()
  File "C:\Python\lib\site-packages\pymysql\connections.py", line 1349, in read
    first_packet = self.connection._read_packet()
  File "C:\Python\lib\site-packages\pymysql\connections.py", line 1018, in _read_packet
    packet.check_error()
  File "C:\Python\lib\site-packages\pymysql\connections.py", line 384, in check_error
    err.raise_mysql_exception(self._data)
  File "C:\Python\lib\site-packages\pymysql\err.py", line 107, in raise_mysql_exception
    raise errorclass(errno, errval)
pymysql.err.ProgrammingError: (1146, "Table 'proxy.proxy' doesn't exist")
2018-Mar-28 18:58:55 proxyDBManager.py[line:102]/ERROR/  ===== mysql insert_proxy exception =====
 (1146, "Table 'proxy.proxy' doesn't exist")
Traceback (most recent call last):
  File "C:\Users\Cheney and Bean\Desktop\Go\mysite\to_travel_here\TravelSpider\proxyPool\dbManager\proxyDBManager.py", line 97, in insert_proxy_table
    self.cursor.execute(insertSql, data)
  File "C:\Python\lib\site-packages\pymysql\cursors.py", line 165, in execute
    result = self._query(query)
  File "C:\Python\lib\site-packages\pymysql\cursors.py", line 321, in _query
    conn.query(q)
  File "C:\Python\lib\site-packages\pymysql\connections.py", line 860, in query
    self._affected_rows = self._read_query_result(unbuffered=unbuffered)
  File "C:\Python\lib\site-packages\pymysql\connections.py", line 1061, in _read_query_result
    result.read()
  File "C:\Python\lib\site-packages\pymysql\connections.py", line 1349, in read
    first_packet = self.connection._read_packet()
  File "C:\Python\lib\site-packages\pymysql\connections.py", line 1018, in _read_packet
    packet.check_error()
  File "C:\Python\lib\site-packages\pymysql\connections.py", line 384, in check_error
    err.raise_mysql_exception(self._data)
  File "C:\Python\lib\site-packages\pymysql\err.py", line 107, in raise_mysql_exception
    raise errorclass(errno, errval)
pymysql.err.ProgrammingError: (1146, "Table 'proxy.proxy' doesn't exist")
2018-Mar-28 18:58:55 proxyDBManager.py[line:102]/ERROR/  ===== mysql insert_proxy exception =====
 (1146, "Table 'proxy.proxy' doesn't exist")
Traceback (most recent call last):
  File "C:\Users\Cheney and Bean\Desktop\Go\mysite\to_travel_here\TravelSpider\proxyPool\dbManager\proxyDBManager.py", line 97, in insert_proxy_table
    self.cursor.execute(insertSql, data)
  File "C:\Python\lib\site-packages\pymysql\cursors.py", line 165, in execute
    result = self._query(query)
  File "C:\Python\lib\site-packages\pymysql\cursors.py", line 321, in _query
    conn.query(q)
  File "C:\Python\lib\site-packages\pymysql\connections.py", line 860, in query
    self._affected_rows = self._read_query_result(unbuffered=unbuffered)
  File "C:\Python\lib\site-packages\pymysql\connections.py", line 1061, in _read_query_result
    result.read()
  File "C:\Python\lib\site-packages\pymysql\connections.py", line 1349, in read
    first_packet = self.connection._read_packet()
  File "C:\Python\lib\site-packages\pymysql\connections.py", line 1018, in _read_packet
    packet.check_error()
  File "C:\Python\lib\site-packages\pymysql\connections.py", line 384, in check_error
    err.raise_mysql_exception(self._data)
  File "C:\Python\lib\site-packages\pymysql\err.py", line 107, in raise_mysql_exception
    raise errorclass(errno, errval)
pymysql.err.ProgrammingError: (1146, "Table 'proxy.proxy' doesn't exist")
2018-Mar-28 18:58:55 proxyDBManager.py[line:102]/ERROR/  ===== mysql insert_proxy exception =====
 (1146, "Table 'proxy.proxy' doesn't exist")
Traceback (most recent call last):
  File "C:\Users\Cheney and Bean\Desktop\Go\mysite\to_travel_here\TravelSpider\proxyPool\dbManager\proxyDBManager.py", line 97, in insert_proxy_table
    self.cursor.execute(insertSql, data)
  File "C:\Python\lib\site-packages\pymysql\cursors.py", line 165, in execute
    result = self._query(query)
  File "C:\Python\lib\site-packages\pymysql\cursors.py", line 321, in _query
    conn.query(q)
  File "C:\Python\lib\site-packages\pymysql\connections.py", line 860, in query
    self._affected_rows = self._read_query_result(unbuffered=unbuffered)
  File "C:\Python\lib\site-packages\pymysql\connections.py", line 1061, in _read_query_result
    result.read()
  File "C:\Python\lib\site-packages\pymysql\connections.py", line 1349, in read
    first_packet = self.connection._read_packet()
  File "C:\Python\lib\site-packages\pymysql\connections.py", line 1018, in _read_packet
    packet.check_error()
  File "C:\Python\lib\site-packages\pymysql\connections.py", line 384, in check_error
    err.raise_mysql_exception(self._data)
  File "C:\Python\lib\site-packages\pymysql\err.py", line 107, in raise_mysql_exception
    raise errorclass(errno, errval)
pymysql.err.ProgrammingError: (1146, "Table 'proxy.proxy' doesn't exist")
2018-Mar-28 18:58:55 proxyDBManager.py[line:102]/ERROR/  ===== mysql insert_proxy exception =====
 (1146, "Table 'proxy.proxy' doesn't exist")
Traceback (most recent call last):
  File "C:\Users\Cheney and Bean\Desktop\Go\mysite\to_travel_here\TravelSpider\proxyPool\dbManager\proxyDBManager.py", line 97, in insert_proxy_table
    self.cursor.execute(insertSql, data)
  File "C:\Python\lib\site-packages\pymysql\cursors.py", line 165, in execute
    result = self._query(query)
  File "C:\Python\lib\site-packages\pymysql\cursors.py", line 321, in _query
    conn.query(q)
  File "C:\Python\lib\site-packages\pymysql\connections.py", line 860, in query
    self._affected_rows = self._read_query_result(unbuffered=unbuffered)
  File "C:\Python\lib\site-packages\pymysql\connections.py", line 1061, in _read_query_result
    result.read()
  File "C:\Python\lib\site-packages\pymysql\connections.py", line 1349, in read
    first_packet = self.connection._read_packet()
  File "C:\Python\lib\site-packages\pymysql\connections.py", line 1018, in _read_packet
    packet.check_error()
  File "C:\Python\lib\site-packages\pymysql\connections.py", line 384, in check_error
    err.raise_mysql_exception(self._data)
  File "C:\Python\lib\site-packages\pymysql\err.py", line 107, in raise_mysql_exception
    raise errorclass(errno, errval)
pymysql.err.ProgrammingError: (1146, "Table 'proxy.proxy' doesn't exist")
2018-Mar-28 18:58:55 proxyDBManager.py[line:102]/ERROR/  ===== mysql insert_proxy exception =====
 (1146, "Table 'proxy.proxy' doesn't exist")
Traceback (most recent call last):
  File "C:\Users\Cheney and Bean\Desktop\Go\mysite\to_travel_here\TravelSpider\proxyPool\dbManager\proxyDBManager.py", line 97, in insert_proxy_table
    self.cursor.execute(insertSql, data)
  File "C:\Python\lib\site-packages\pymysql\cursors.py", line 165, in execute
    result = self._query(query)
  File "C:\Python\lib\site-packages\pymysql\cursors.py", line 321, in _query
    conn.query(q)
  File "C:\Python\lib\site-packages\pymysql\connections.py", line 860, in query
    self._affected_rows = self._read_query_result(unbuffered=unbuffered)
  File "C:\Python\lib\site-packages\pymysql\connections.py", line 1061, in _read_query_result
    result.read()
  File "C:\Python\lib\site-packages\pymysql\connections.py", line 1349, in read
    first_packet = self.connection._read_packet()
  File "C:\Python\lib\site-packages\pymysql\connections.py", line 1018, in _read_packet
    packet.check_error()
  File "C:\Python\lib\site-packages\pymysql\connections.py", line 384, in check_error
    err.raise_mysql_exception(self._data)
  File "C:\Python\lib\site-packages\pymysql\err.py", line 107, in raise_mysql_exception
    raise errorclass(errno, errval)
pymysql.err.ProgrammingError: (1146, "Table 'proxy.proxy' doesn't exist")
2018-Mar-28 18:58:55 proxyDBManager.py[line:102]/ERROR/  ===== mysql insert_proxy exception =====
 (1146, "Table 'proxy.proxy' doesn't exist")
Traceback (most recent call last):
  File "C:\Users\Cheney and Bean\Desktop\Go\mysite\to_travel_here\TravelSpider\proxyPool\dbManager\proxyDBManager.py", line 97, in insert_proxy_table
    self.cursor.execute(insertSql, data)
  File "C:\Python\lib\site-packages\pymysql\cursors.py", line 165, in execute
    result = self._query(query)
  File "C:\Python\lib\site-packages\pymysql\cursors.py", line 321, in _query
    conn.query(q)
  File "C:\Python\lib\site-packages\pymysql\connections.py", line 860, in query
    self._affected_rows = self._read_query_result(unbuffered=unbuffered)
  File "C:\Python\lib\site-packages\pymysql\connections.py", line 1061, in _read_query_result
    result.read()
  File "C:\Python\lib\site-packages\pymysql\connections.py", line 1349, in read
    first_packet = self.connection._read_packet()
  File "C:\Python\lib\site-packages\pymysql\connections.py", line 1018, in _read_packet
    packet.check_error()
  File "C:\Python\lib\site-packages\pymysql\connections.py", line 384, in check_error
    err.raise_mysql_exception(self._data)
  File "C:\Python\lib\site-packages\pymysql\err.py", line 107, in raise_mysql_exception
    raise errorclass(errno, errval)
pymysql.err.ProgrammingError: (1146, "Table 'proxy.proxy' doesn't exist")
2018-Mar-28 18:58:55 proxyDBManager.py[line:102]/ERROR/  ===== mysql insert_proxy exception =====
 (1146, "Table 'proxy.proxy' doesn't exist")
Traceback (most recent call last):
  File "C:\Users\Cheney and Bean\Desktop\Go\mysite\to_travel_here\TravelSpider\proxyPool\dbManager\proxyDBManager.py", line 97, in insert_proxy_table
    self.cursor.execute(insertSql, data)
  File "C:\Python\lib\site-packages\pymysql\cursors.py", line 165, in execute
    result = self._query(query)
  File "C:\Python\lib\site-packages\pymysql\cursors.py", line 321, in _query
    conn.query(q)
  File "C:\Python\lib\site-packages\pymysql\connections.py", line 860, in query
    self._affected_rows = self._read_query_result(unbuffered=unbuffered)
  File "C:\Python\lib\site-packages\pymysql\connections.py", line 1061, in _read_query_result
    result.read()
  File "C:\Python\lib\site-packages\pymysql\connections.py", line 1349, in read
    first_packet = self.connection._read_packet()
  File "C:\Python\lib\site-packages\pymysql\connections.py", line 1018, in _read_packet
    packet.check_error()
  File "C:\Python\lib\site-packages\pymysql\connections.py", line 384, in check_error
    err.raise_mysql_exception(self._data)
  File "C:\Python\lib\site-packages\pymysql\err.py", line 107, in raise_mysql_exception
    raise errorclass(errno, errval)
pymysql.err.ProgrammingError: (1146, "Table 'proxy.proxy' doesn't exist")
2018-Mar-28 18:58:55 proxyDBManager.py[line:102]/ERROR/  ===== mysql insert_proxy exception =====
 (1146, "Table 'proxy.proxy' doesn't exist")
Traceback (most recent call last):
  File "C:\Users\Cheney and Bean\Desktop\Go\mysite\to_travel_here\TravelSpider\proxyPool\dbManager\proxyDBManager.py", line 97, in insert_proxy_table
    self.cursor.execute(insertSql, data)
  File "C:\Python\lib\site-packages\pymysql\cursors.py", line 165, in execute
    result = self._query(query)
  File "C:\Python\lib\site-packages\pymysql\cursors.py", line 321, in _query
    conn.query(q)
  File "C:\Python\lib\site-packages\pymysql\connections.py", line 860, in query
    self._affected_rows = self._read_query_result(unbuffered=unbuffered)
  File "C:\Python\lib\site-packages\pymysql\connections.py", line 1061, in _read_query_result
    result.read()
  File "C:\Python\lib\site-packages\pymysql\connections.py", line 1349, in read
    first_packet = self.connection._read_packet()
  File "C:\Python\lib\site-packages\pymysql\connections.py", line 1018, in _read_packet
    packet.check_error()
  File "C:\Python\lib\site-packages\pymysql\connections.py", line 384, in check_error
    err.raise_mysql_exception(self._data)
  File "C:\Python\lib\site-packages\pymysql\err.py", line 107, in raise_mysql_exception
    raise errorclass(errno, errval)
pymysql.err.ProgrammingError: (1146, "Table 'proxy.proxy' doesn't exist")
2018-Mar-28 18:58:55 proxyDBManager.py[line:102]/ERROR/  ===== mysql insert_proxy exception =====
 (1146, "Table 'proxy.proxy' doesn't exist")
Traceback (most recent call last):
  File "C:\Users\Cheney and Bean\Desktop\Go\mysite\to_travel_here\TravelSpider\proxyPool\dbManager\proxyDBManager.py", line 97, in insert_proxy_table
    self.cursor.execute(insertSql, data)
  File "C:\Python\lib\site-packages\pymysql\cursors.py", line 165, in execute
    result = self._query(query)
  File "C:\Python\lib\site-packages\pymysql\cursors.py", line 321, in _query
    conn.query(q)
  File "C:\Python\lib\site-packages\pymysql\connections.py", line 860, in query
    self._affected_rows = self._read_query_result(unbuffered=unbuffered)
  File "C:\Python\lib\site-packages\pymysql\connections.py", line 1061, in _read_query_result
    result.read()
  File "C:\Python\lib\site-packages\pymysql\connections.py", line 1349, in read
    first_packet = self.connection._read_packet()
  File "C:\Python\lib\site-packages\pymysql\connections.py", line 1018, in _read_packet
    packet.check_error()
  File "C:\Python\lib\site-packages\pymysql\connections.py", line 384, in check_error
    err.raise_mysql_exception(self._data)
  File "C:\Python\lib\site-packages\pymysql\err.py", line 107, in raise_mysql_exception
    raise errorclass(errno, errval)
pymysql.err.ProgrammingError: (1146, "Table 'proxy.proxy' doesn't exist")
2018-Mar-28 18:58:55 proxyDBManager.py[line:102]/ERROR/  ===== mysql insert_proxy exception =====
 (1146, "Table 'proxy.proxy' doesn't exist")
Traceback (most recent call last):
  File "C:\Users\Cheney and Bean\Desktop\Go\mysite\to_travel_here\TravelSpider\proxyPool\dbManager\proxyDBManager.py", line 97, in insert_proxy_table
    self.cursor.execute(insertSql, data)
  File "C:\Python\lib\site-packages\pymysql\cursors.py", line 165, in execute
    result = self._query(query)
  File "C:\Python\lib\site-packages\pymysql\cursors.py", line 321, in _query
    conn.query(q)
  File "C:\Python\lib\site-packages\pymysql\connections.py", line 860, in query
    self._affected_rows = self._read_query_result(unbuffered=unbuffered)
  File "C:\Python\lib\site-packages\pymysql\connections.py", line 1061, in _read_query_result
    result.read()
  File "C:\Python\lib\site-packages\pymysql\connections.py", line 1349, in read
    first_packet = self.connection._read_packet()
  File "C:\Python\lib\site-packages\pymysql\connections.py", line 1018, in _read_packet
    packet.check_error()
  File "C:\Python\lib\site-packages\pymysql\connections.py", line 384, in check_error
    err.raise_mysql_exception(self._data)
  File "C:\Python\lib\site-packages\pymysql\err.py", line 107, in raise_mysql_exception
    raise errorclass(errno, errval)
pymysql.err.ProgrammingError: (1146, "Table 'proxy.proxy' doesn't exist")
2018-Mar-28 18:58:55 proxyDBManager.py[line:102]/ERROR/  ===== mysql insert_proxy exception =====
 (1146, "Table 'proxy.proxy' doesn't exist")
Traceback (most recent call last):
  File "C:\Users\Cheney and Bean\Desktop\Go\mysite\to_travel_here\TravelSpider\proxyPool\dbManager\proxyDBManager.py", line 97, in insert_proxy_table
    self.cursor.execute(insertSql, data)
  File "C:\Python\lib\site-packages\pymysql\cursors.py", line 165, in execute
    result = self._query(query)
  File "C:\Python\lib\site-packages\pymysql\cursors.py", line 321, in _query
    conn.query(q)
  File "C:\Python\lib\site-packages\pymysql\connections.py", line 860, in query
    self._affected_rows = self._read_query_result(unbuffered=unbuffered)
  File "C:\Python\lib\site-packages\pymysql\connections.py", line 1061, in _read_query_result
    result.read()
  File "C:\Python\lib\site-packages\pymysql\connections.py", line 1349, in read
    first_packet = self.connection._read_packet()
  File "C:\Python\lib\site-packages\pymysql\connections.py", line 1018, in _read_packet
    packet.check_error()
  File "C:\Python\lib\site-packages\pymysql\connections.py", line 384, in check_error
    err.raise_mysql_exception(self._data)
  File "C:\Python\lib\site-packages\pymysql\err.py", line 107, in raise_mysql_exception
    raise errorclass(errno, errval)
pymysql.err.ProgrammingError: (1146, "Table 'proxy.proxy' doesn't exist")
2018-Mar-28 18:58:55 proxyDBManager.py[line:102]/ERROR/  ===== mysql insert_proxy exception =====
 (1146, "Table 'proxy.proxy' doesn't exist")
Traceback (most recent call last):
  File "C:\Users\Cheney and Bean\Desktop\Go\mysite\to_travel_here\TravelSpider\proxyPool\dbManager\proxyDBManager.py", line 97, in insert_proxy_table
    self.cursor.execute(insertSql, data)
  File "C:\Python\lib\site-packages\pymysql\cursors.py", line 165, in execute
    result = self._query(query)
  File "C:\Python\lib\site-packages\pymysql\cursors.py", line 321, in _query
    conn.query(q)
  File "C:\Python\lib\site-packages\pymysql\connections.py", line 860, in query
    self._affected_rows = self._read_query_result(unbuffered=unbuffered)
  File "C:\Python\lib\site-packages\pymysql\connections.py", line 1061, in _read_query_result
    result.read()
  File "C:\Python\lib\site-packages\pymysql\connections.py", line 1349, in read
    first_packet = self.connection._read_packet()
  File "C:\Python\lib\site-packages\pymysql\connections.py", line 1018, in _read_packet
    packet.check_error()
  File "C:\Python\lib\site-packages\pymysql\connections.py", line 384, in check_error
    err.raise_mysql_exception(self._data)
  File "C:\Python\lib\site-packages\pymysql\err.py", line 107, in raise_mysql_exception
    raise errorclass(errno, errval)
pymysql.err.ProgrammingError: (1146, "Table 'proxy.proxy' doesn't exist")
2018-Mar-28 18:58:55 proxyDBManager.py[line:102]/ERROR/  ===== mysql insert_proxy exception =====
 (1146, "Table 'proxy.proxy' doesn't exist")
Traceback (most recent call last):
  File "C:\Users\Cheney and Bean\Desktop\Go\mysite\to_travel_here\TravelSpider\proxyPool\dbManager\proxyDBManager.py", line 97, in insert_proxy_table
    self.cursor.execute(insertSql, data)
  File "C:\Python\lib\site-packages\pymysql\cursors.py", line 165, in execute
    result = self._query(query)
  File "C:\Python\lib\site-packages\pymysql\cursors.py", line 321, in _query
    conn.query(q)
  File "C:\Python\lib\site-packages\pymysql\connections.py", line 860, in query
    self._affected_rows = self._read_query_result(unbuffered=unbuffered)
  File "C:\Python\lib\site-packages\pymysql\connections.py", line 1061, in _read_query_result
    result.read()
  File "C:\Python\lib\site-packages\pymysql\connections.py", line 1349, in read
    first_packet = self.connection._read_packet()
  File "C:\Python\lib\site-packages\pymysql\connections.py", line 1018, in _read_packet
    packet.check_error()
  File "C:\Python\lib\site-packages\pymysql\connections.py", line 384, in check_error
    err.raise_mysql_exception(self._data)
  File "C:\Python\lib\site-packages\pymysql\err.py", line 107, in raise_mysql_exception
    raise errorclass(errno, errval)
pymysql.err.ProgrammingError: (1146, "Table 'proxy.proxy' doesn't exist")
2018-Mar-28 18:58:55 proxyDBManager.py[line:102]/ERROR/  ===== mysql insert_proxy exception =====
 (1146, "Table 'proxy.proxy' doesn't exist")
Traceback (most recent call last):
  File "C:\Users\Cheney and Bean\Desktop\Go\mysite\to_travel_here\TravelSpider\proxyPool\dbManager\proxyDBManager.py", line 97, in insert_proxy_table
    self.cursor.execute(insertSql, data)
  File "C:\Python\lib\site-packages\pymysql\cursors.py", line 165, in execute
    result = self._query(query)
  File "C:\Python\lib\site-packages\pymysql\cursors.py", line 321, in _query
    conn.query(q)
  File "C:\Python\lib\site-packages\pymysql\connections.py", line 860, in query
    self._affected_rows = self._read_query_result(unbuffered=unbuffered)
  File "C:\Python\lib\site-packages\pymysql\connections.py", line 1061, in _read_query_result
    result.read()
  File "C:\Python\lib\site-packages\pymysql\connections.py", line 1349, in read
    first_packet = self.connection._read_packet()
  File "C:\Python\lib\site-packages\pymysql\connections.py", line 1018, in _read_packet
    packet.check_error()
  File "C:\Python\lib\site-packages\pymysql\connections.py", line 384, in check_error
    err.raise_mysql_exception(self._data)
  File "C:\Python\lib\site-packages\pymysql\err.py", line 107, in raise_mysql_exception
    raise errorclass(errno, errval)
pymysql.err.ProgrammingError: (1146, "Table 'proxy.proxy' doesn't exist")
2018-Mar-28 18:58:55 proxyDBManager.py[line:102]/ERROR/  ===== mysql insert_proxy exception =====
 (1146, "Table 'proxy.proxy' doesn't exist")
Traceback (most recent call last):
  File "C:\Users\Cheney and Bean\Desktop\Go\mysite\to_travel_here\TravelSpider\proxyPool\dbManager\proxyDBManager.py", line 97, in insert_proxy_table
    self.cursor.execute(insertSql, data)
  File "C:\Python\lib\site-packages\pymysql\cursors.py", line 165, in execute
    result = self._query(query)
  File "C:\Python\lib\site-packages\pymysql\cursors.py", line 321, in _query
    conn.query(q)
  File "C:\Python\lib\site-packages\pymysql\connections.py", line 860, in query
    self._affected_rows = self._read_query_result(unbuffered=unbuffered)
  File "C:\Python\lib\site-packages\pymysql\connections.py", line 1061, in _read_query_result
    result.read()
  File "C:\Python\lib\site-packages\pymysql\connections.py", line 1349, in read
    first_packet = self.connection._read_packet()
  File "C:\Python\lib\site-packages\pymysql\connections.py", line 1018, in _read_packet
    packet.check_error()
  File "C:\Python\lib\site-packages\pymysql\connections.py", line 384, in check_error
    err.raise_mysql_exception(self._data)
  File "C:\Python\lib\site-packages\pymysql\err.py", line 107, in raise_mysql_exception
    raise errorclass(errno, errval)
pymysql.err.ProgrammingError: (1146, "Table 'proxy.proxy' doesn't exist")
2018-Mar-28 18:58:55 proxyDBManager.py[line:102]/ERROR/  ===== mysql insert_proxy exception =====
 (1146, "Table 'proxy.proxy' doesn't exist")
Traceback (most recent call last):
  File "C:\Users\Cheney and Bean\Desktop\Go\mysite\to_travel_here\TravelSpider\proxyPool\dbManager\proxyDBManager.py", line 97, in insert_proxy_table
    self.cursor.execute(insertSql, data)
  File "C:\Python\lib\site-packages\pymysql\cursors.py", line 165, in execute
    result = self._query(query)
  File "C:\Python\lib\site-packages\pymysql\cursors.py", line 321, in _query
    conn.query(q)
  File "C:\Python\lib\site-packages\pymysql\connections.py", line 860, in query
    self._affected_rows = self._read_query_result(unbuffered=unbuffered)
  File "C:\Python\lib\site-packages\pymysql\connections.py", line 1061, in _read_query_result
    result.read()
  File "C:\Python\lib\site-packages\pymysql\connections.py", line 1349, in read
    first_packet = self.connection._read_packet()
  File "C:\Python\lib\site-packages\pymysql\connections.py", line 1018, in _read_packet
    packet.check_error()
  File "C:\Python\lib\site-packages\pymysql\connections.py", line 384, in check_error
    err.raise_mysql_exception(self._data)
  File "C:\Python\lib\site-packages\pymysql\err.py", line 107, in raise_mysql_exception
    raise errorclass(errno, errval)
pymysql.err.ProgrammingError: (1146, "Table 'proxy.proxy' doesn't exist")
2018-Mar-28 18:58:55 proxyDBManager.py[line:102]/ERROR/  ===== mysql insert_proxy exception =====
 (1146, "Table 'proxy.proxy' doesn't exist")
Traceback (most recent call last):
  File "C:\Users\Cheney and Bean\Desktop\Go\mysite\to_travel_here\TravelSpider\proxyPool\dbManager\proxyDBManager.py", line 97, in insert_proxy_table
    self.cursor.execute(insertSql, data)
  File "C:\Python\lib\site-packages\pymysql\cursors.py", line 165, in execute
    result = self._query(query)
  File "C:\Python\lib\site-packages\pymysql\cursors.py", line 321, in _query
    conn.query(q)
  File "C:\Python\lib\site-packages\pymysql\connections.py", line 860, in query
    self._affected_rows = self._read_query_result(unbuffered=unbuffered)
  File "C:\Python\lib\site-packages\pymysql\connections.py", line 1061, in _read_query_result
    result.read()
  File "C:\Python\lib\site-packages\pymysql\connections.py", line 1349, in read
    first_packet = self.connection._read_packet()
  File "C:\Python\lib\site-packages\pymysql\connections.py", line 1018, in _read_packet
    packet.check_error()
  File "C:\Python\lib\site-packages\pymysql\connections.py", line 384, in check_error
    err.raise_mysql_exception(self._data)
  File "C:\Python\lib\site-packages\pymysql\err.py", line 107, in raise_mysql_exception
    raise errorclass(errno, errval)
pymysql.err.ProgrammingError: (1146, "Table 'proxy.proxy' doesn't exist")
2018-Mar-28 18:58:55 proxyDBManager.py[line:102]/ERROR/  ===== mysql insert_proxy exception =====
 (1146, "Table 'proxy.proxy' doesn't exist")
Traceback (most recent call last):
  File "C:\Users\Cheney and Bean\Desktop\Go\mysite\to_travel_here\TravelSpider\proxyPool\dbManager\proxyDBManager.py", line 97, in insert_proxy_table
    self.cursor.execute(insertSql, data)
  File "C:\Python\lib\site-packages\pymysql\cursors.py", line 165, in execute
    result = self._query(query)
  File "C:\Python\lib\site-packages\pymysql\cursors.py", line 321, in _query
    conn.query(q)
  File "C:\Python\lib\site-packages\pymysql\connections.py", line 860, in query
    self._affected_rows = self._read_query_result(unbuffered=unbuffered)
  File "C:\Python\lib\site-packages\pymysql\connections.py", line 1061, in _read_query_result
    result.read()
  File "C:\Python\lib\site-packages\pymysql\connections.py", line 1349, in read
    first_packet = self.connection._read_packet()
  File "C:\Python\lib\site-packages\pymysql\connections.py", line 1018, in _read_packet
    packet.check_error()
  File "C:\Python\lib\site-packages\pymysql\connections.py", line 384, in check_error
    err.raise_mysql_exception(self._data)
  File "C:\Python\lib\site-packages\pymysql\err.py", line 107, in raise_mysql_exception
    raise errorclass(errno, errval)
pymysql.err.ProgrammingError: (1146, "Table 'proxy.proxy' doesn't exist")
2018-Mar-28 18:58:55 proxyDBManager.py[line:102]/ERROR/  ===== mysql insert_proxy exception =====
 (1146, "Table 'proxy.proxy' doesn't exist")
Traceback (most recent call last):
  File "C:\Users\Cheney and Bean\Desktop\Go\mysite\to_travel_here\TravelSpider\proxyPool\dbManager\proxyDBManager.py", line 97, in insert_proxy_table
    self.cursor.execute(insertSql, data)
  File "C:\Python\lib\site-packages\pymysql\cursors.py", line 165, in execute
    result = self._query(query)
  File "C:\Python\lib\site-packages\pymysql\cursors.py", line 321, in _query
    conn.query(q)
  File "C:\Python\lib\site-packages\pymysql\connections.py", line 860, in query
    self._affected_rows = self._read_query_result(unbuffered=unbuffered)
  File "C:\Python\lib\site-packages\pymysql\connections.py", line 1061, in _read_query_result
    result.read()
  File "C:\Python\lib\site-packages\pymysql\connections.py", line 1349, in read
    first_packet = self.connection._read_packet()
  File "C:\Python\lib\site-packages\pymysql\connections.py", line 1018, in _read_packet
    packet.check_error()
  File "C:\Python\lib\site-packages\pymysql\connections.py", line 384, in check_error
    err.raise_mysql_exception(self._data)
  File "C:\Python\lib\site-packages\pymysql\err.py", line 107, in raise_mysql_exception
    raise errorclass(errno, errval)
pymysql.err.ProgrammingError: (1146, "Table 'proxy.proxy' doesn't exist")
2018-Mar-28 18:58:55 proxyDBManager.py[line:102]/ERROR/  ===== mysql insert_proxy exception =====
 (1146, "Table 'proxy.proxy' doesn't exist")
Traceback (most recent call last):
  File "C:\Users\Cheney and Bean\Desktop\Go\mysite\to_travel_here\TravelSpider\proxyPool\dbManager\proxyDBManager.py", line 97, in insert_proxy_table
    self.cursor.execute(insertSql, data)
  File "C:\Python\lib\site-packages\pymysql\cursors.py", line 165, in execute
    result = self._query(query)
  File "C:\Python\lib\site-packages\pymysql\cursors.py", line 321, in _query
    conn.query(q)
  File "C:\Python\lib\site-packages\pymysql\connections.py", line 860, in query
    self._affected_rows = self._read_query_result(unbuffered=unbuffered)
  File "C:\Python\lib\site-packages\pymysql\connections.py", line 1061, in _read_query_result
    result.read()
  File "C:\Python\lib\site-packages\pymysql\connections.py", line 1349, in read
    first_packet = self.connection._read_packet()
  File "C:\Python\lib\site-packages\pymysql\connections.py", line 1018, in _read_packet
    packet.check_error()
  File "C:\Python\lib\site-packages\pymysql\connections.py", line 384, in check_error
    err.raise_mysql_exception(self._data)
  File "C:\Python\lib\site-packages\pymysql\err.py", line 107, in raise_mysql_exception
    raise errorclass(errno, errval)
pymysql.err.ProgrammingError: (1146, "Table 'proxy.proxy' doesn't exist")
2018-Mar-28 18:58:55 proxyDBManager.py[line:102]/ERROR/  ===== mysql insert_proxy exception =====
 (1146, "Table 'proxy.proxy' doesn't exist")
Traceback (most recent call last):
  File "C:\Users\Cheney and Bean\Desktop\Go\mysite\to_travel_here\TravelSpider\proxyPool\dbManager\proxyDBManager.py", line 97, in insert_proxy_table
    self.cursor.execute(insertSql, data)
  File "C:\Python\lib\site-packages\pymysql\cursors.py", line 165, in execute
    result = self._query(query)
  File "C:\Python\lib\site-packages\pymysql\cursors.py", line 321, in _query
    conn.query(q)
  File "C:\Python\lib\site-packages\pymysql\connections.py", line 860, in query
    self._affected_rows = self._read_query_result(unbuffered=unbuffered)
  File "C:\Python\lib\site-packages\pymysql\connections.py", line 1061, in _read_query_result
    result.read()
  File "C:\Python\lib\site-packages\pymysql\connections.py", line 1349, in read
    first_packet = self.connection._read_packet()
  File "C:\Python\lib\site-packages\pymysql\connections.py", line 1018, in _read_packet
    packet.check_error()
  File "C:\Python\lib\site-packages\pymysql\connections.py", line 384, in check_error
    err.raise_mysql_exception(self._data)
  File "C:\Python\lib\site-packages\pymysql\err.py", line 107, in raise_mysql_exception
    raise errorclass(errno, errval)
pymysql.err.ProgrammingError: (1146, "Table 'proxy.proxy' doesn't exist")
2018-Mar-28 18:58:55 proxyDBManager.py[line:102]/ERROR/  ===== mysql insert_proxy exception =====
 (1146, "Table 'proxy.proxy' doesn't exist")
Traceback (most recent call last):
  File "C:\Users\Cheney and Bean\Desktop\Go\mysite\to_travel_here\TravelSpider\proxyPool\dbManager\proxyDBManager.py", line 97, in insert_proxy_table
    self.cursor.execute(insertSql, data)
  File "C:\Python\lib\site-packages\pymysql\cursors.py", line 165, in execute
    result = self._query(query)
  File "C:\Python\lib\site-packages\pymysql\cursors.py", line 321, in _query
    conn.query(q)
  File "C:\Python\lib\site-packages\pymysql\connections.py", line 860, in query
    self._affected_rows = self._read_query_result(unbuffered=unbuffered)
  File "C:\Python\lib\site-packages\pymysql\connections.py", line 1061, in _read_query_result
    result.read()
  File "C:\Python\lib\site-packages\pymysql\connections.py", line 1349, in read
    first_packet = self.connection._read_packet()
  File "C:\Python\lib\site-packages\pymysql\connections.py", line 1018, in _read_packet
    packet.check_error()
  File "C:\Python\lib\site-packages\pymysql\connections.py", line 384, in check_error
    err.raise_mysql_exception(self._data)
  File "C:\Python\lib\site-packages\pymysql\err.py", line 107, in raise_mysql_exception
    raise errorclass(errno, errval)
pymysql.err.ProgrammingError: (1146, "Table 'proxy.proxy' doesn't exist")
2018-Mar-28 18:58:55 proxyDBManager.py[line:102]/ERROR/  ===== mysql insert_proxy exception =====
 (1146, "Table 'proxy.proxy' doesn't exist")
Traceback (most recent call last):
  File "C:\Users\Cheney and Bean\Desktop\Go\mysite\to_travel_here\TravelSpider\proxyPool\dbManager\proxyDBManager.py", line 97, in insert_proxy_table
    self.cursor.execute(insertSql, data)
  File "C:\Python\lib\site-packages\pymysql\cursors.py", line 165, in execute
    result = self._query(query)
  File "C:\Python\lib\site-packages\pymysql\cursors.py", line 321, in _query
    conn.query(q)
  File "C:\Python\lib\site-packages\pymysql\connections.py", line 860, in query
    self._affected_rows = self._read_query_result(unbuffered=unbuffered)
  File "C:\Python\lib\site-packages\pymysql\connections.py", line 1061, in _read_query_result
    result.read()
  File "C:\Python\lib\site-packages\pymysql\connections.py", line 1349, in read
    first_packet = self.connection._read_packet()
  File "C:\Python\lib\site-packages\pymysql\connections.py", line 1018, in _read_packet
    packet.check_error()
  File "C:\Python\lib\site-packages\pymysql\connections.py", line 384, in check_error
    err.raise_mysql_exception(self._data)
  File "C:\Python\lib\site-packages\pymysql\err.py", line 107, in raise_mysql_exception
    raise errorclass(errno, errval)
pymysql.err.ProgrammingError: (1146, "Table 'proxy.proxy' doesn't exist")
2018-Mar-28 18:58:55 proxyDBManager.py[line:102]/ERROR/  ===== mysql insert_proxy exception =====
 (1146, "Table 'proxy.proxy' doesn't exist")
Traceback (most recent call last):
  File "C:\Users\Cheney and Bean\Desktop\Go\mysite\to_travel_here\TravelSpider\proxyPool\dbManager\proxyDBManager.py", line 97, in insert_proxy_table
    self.cursor.execute(insertSql, data)
  File "C:\Python\lib\site-packages\pymysql\cursors.py", line 165, in execute
    result = self._query(query)
  File "C:\Python\lib\site-packages\pymysql\cursors.py", line 321, in _query
    conn.query(q)
  File "C:\Python\lib\site-packages\pymysql\connections.py", line 860, in query
    self._affected_rows = self._read_query_result(unbuffered=unbuffered)
  File "C:\Python\lib\site-packages\pymysql\connections.py", line 1061, in _read_query_result
    result.read()
  File "C:\Python\lib\site-packages\pymysql\connections.py", line 1349, in read
    first_packet = self.connection._read_packet()
  File "C:\Python\lib\site-packages\pymysql\connections.py", line 1018, in _read_packet
    packet.check_error()
  File "C:\Python\lib\site-packages\pymysql\connections.py", line 384, in check_error
    err.raise_mysql_exception(self._data)
  File "C:\Python\lib\site-packages\pymysql\err.py", line 107, in raise_mysql_exception
    raise errorclass(errno, errval)
pymysql.err.ProgrammingError: (1146, "Table 'proxy.proxy' doesn't exist")
2018-Mar-28 18:58:55 proxyDBManager.py[line:102]/ERROR/  ===== mysql insert_proxy exception =====
 (1146, "Table 'proxy.proxy' doesn't exist")
Traceback (most recent call last):
  File "C:\Users\Cheney and Bean\Desktop\Go\mysite\to_travel_here\TravelSpider\proxyPool\dbManager\proxyDBManager.py", line 97, in insert_proxy_table
    self.cursor.execute(insertSql, data)
  File "C:\Python\lib\site-packages\pymysql\cursors.py", line 165, in execute
    result = self._query(query)
  File "C:\Python\lib\site-packages\pymysql\cursors.py", line 321, in _query
    conn.query(q)
  File "C:\Python\lib\site-packages\pymysql\connections.py", line 860, in query
    self._affected_rows = self._read_query_result(unbuffered=unbuffered)
  File "C:\Python\lib\site-packages\pymysql\connections.py", line 1061, in _read_query_result
    result.read()
  File "C:\Python\lib\site-packages\pymysql\connections.py", line 1349, in read
    first_packet = self.connection._read_packet()
  File "C:\Python\lib\site-packages\pymysql\connections.py", line 1018, in _read_packet
    packet.check_error()
  File "C:\Python\lib\site-packages\pymysql\connections.py", line 384, in check_error
    err.raise_mysql_exception(self._data)
  File "C:\Python\lib\site-packages\pymysql\err.py", line 107, in raise_mysql_exception
    raise errorclass(errno, errval)
pymysql.err.ProgrammingError: (1146, "Table 'proxy.proxy' doesn't exist")
2018-Mar-28 18:58:55 proxyDBManager.py[line:102]/ERROR/  ===== mysql insert_proxy exception =====
 (1146, "Table 'proxy.proxy' doesn't exist")
Traceback (most recent call last):
  File "C:\Users\Cheney and Bean\Desktop\Go\mysite\to_travel_here\TravelSpider\proxyPool\dbManager\proxyDBManager.py", line 97, in insert_proxy_table
    self.cursor.execute(insertSql, data)
  File "C:\Python\lib\site-packages\pymysql\cursors.py", line 165, in execute
    result = self._query(query)
  File "C:\Python\lib\site-packages\pymysql\cursors.py", line 321, in _query
    conn.query(q)
  File "C:\Python\lib\site-packages\pymysql\connections.py", line 860, in query
    self._affected_rows = self._read_query_result(unbuffered=unbuffered)
  File "C:\Python\lib\site-packages\pymysql\connections.py", line 1061, in _read_query_result
    result.read()
  File "C:\Python\lib\site-packages\pymysql\connections.py", line 1349, in read
    first_packet = self.connection._read_packet()
  File "C:\Python\lib\site-packages\pymysql\connections.py", line 1018, in _read_packet
    packet.check_error()
  File "C:\Python\lib\site-packages\pymysql\connections.py", line 384, in check_error
    err.raise_mysql_exception(self._data)
  File "C:\Python\lib\site-packages\pymysql\err.py", line 107, in raise_mysql_exception
    raise errorclass(errno, errval)
pymysql.err.ProgrammingError: (1146, "Table 'proxy.proxy' doesn't exist")
2018-Mar-28 18:58:55 proxyDBManager.py[line:102]/ERROR/  ===== mysql insert_proxy exception =====
 (1146, "Table 'proxy.proxy' doesn't exist")
Traceback (most recent call last):
  File "C:\Users\Cheney and Bean\Desktop\Go\mysite\to_travel_here\TravelSpider\proxyPool\dbManager\proxyDBManager.py", line 97, in insert_proxy_table
    self.cursor.execute(insertSql, data)
  File "C:\Python\lib\site-packages\pymysql\cursors.py", line 165, in execute
    result = self._query(query)
  File "C:\Python\lib\site-packages\pymysql\cursors.py", line 321, in _query
    conn.query(q)
  File "C:\Python\lib\site-packages\pymysql\connections.py", line 860, in query
    self._affected_rows = self._read_query_result(unbuffered=unbuffered)
  File "C:\Python\lib\site-packages\pymysql\connections.py", line 1061, in _read_query_result
    result.read()
  File "C:\Python\lib\site-packages\pymysql\connections.py", line 1349, in read
    first_packet = self.connection._read_packet()
  File "C:\Python\lib\site-packages\pymysql\connections.py", line 1018, in _read_packet
    packet.check_error()
  File "C:\Python\lib\site-packages\pymysql\connections.py", line 384, in check_error
    err.raise_mysql_exception(self._data)
  File "C:\Python\lib\site-packages\pymysql\err.py", line 107, in raise_mysql_exception
    raise errorclass(errno, errval)
pymysql.err.ProgrammingError: (1146, "Table 'proxy.proxy' doesn't exist")
2018-Mar-28 18:58:55 proxyDBManager.py[line:102]/ERROR/  ===== mysql insert_proxy exception =====
 (1146, "Table 'proxy.proxy' doesn't exist")
Traceback (most recent call last):
  File "C:\Users\Cheney and Bean\Desktop\Go\mysite\to_travel_here\TravelSpider\proxyPool\dbManager\proxyDBManager.py", line 97, in insert_proxy_table
    self.cursor.execute(insertSql, data)
  File "C:\Python\lib\site-packages\pymysql\cursors.py", line 165, in execute
    result = self._query(query)
  File "C:\Python\lib\site-packages\pymysql\cursors.py", line 321, in _query
    conn.query(q)
  File "C:\Python\lib\site-packages\pymysql\connections.py", line 860, in query
    self._affected_rows = self._read_query_result(unbuffered=unbuffered)
  File "C:\Python\lib\site-packages\pymysql\connections.py", line 1061, in _read_query_result
    result.read()
  File "C:\Python\lib\site-packages\pymysql\connections.py", line 1349, in read
    first_packet = self.connection._read_packet()
  File "C:\Python\lib\site-packages\pymysql\connections.py", line 1018, in _read_packet
    packet.check_error()
  File "C:\Python\lib\site-packages\pymysql\connections.py", line 384, in check_error
    err.raise_mysql_exception(self._data)
  File "C:\Python\lib\site-packages\pymysql\err.py", line 107, in raise_mysql_exception
    raise errorclass(errno, errval)
pymysql.err.ProgrammingError: (1146, "Table 'proxy.proxy' doesn't exist")
2018-Mar-28 18:58:55 proxyDBManager.py[line:102]/ERROR/  ===== mysql insert_proxy exception =====
 (1146, "Table 'proxy.proxy' doesn't exist")
Traceback (most recent call last):
  File "C:\Users\Cheney and Bean\Desktop\Go\mysite\to_travel_here\TravelSpider\proxyPool\dbManager\proxyDBManager.py", line 97, in insert_proxy_table
    self.cursor.execute(insertSql, data)
  File "C:\Python\lib\site-packages\pymysql\cursors.py", line 165, in execute
    result = self._query(query)
  File "C:\Python\lib\site-packages\pymysql\cursors.py", line 321, in _query
    conn.query(q)
  File "C:\Python\lib\site-packages\pymysql\connections.py", line 860, in query
    self._affected_rows = self._read_query_result(unbuffered=unbuffered)
  File "C:\Python\lib\site-packages\pymysql\connections.py", line 1061, in _read_query_result
    result.read()
  File "C:\Python\lib\site-packages\pymysql\connections.py", line 1349, in read
    first_packet = self.connection._read_packet()
  File "C:\Python\lib\site-packages\pymysql\connections.py", line 1018, in _read_packet
    packet.check_error()
  File "C:\Python\lib\site-packages\pymysql\connections.py", line 384, in check_error
    err.raise_mysql_exception(self._data)
  File "C:\Python\lib\site-packages\pymysql\err.py", line 107, in raise_mysql_exception
    raise errorclass(errno, errval)
pymysql.err.ProgrammingError: (1146, "Table 'proxy.proxy' doesn't exist")
2018-Mar-28 18:58:55 proxyDBManager.py[line:102]/ERROR/  ===== mysql insert_proxy exception =====
 (1146, "Table 'proxy.proxy' doesn't exist")
Traceback (most recent call last):
  File "C:\Users\Cheney and Bean\Desktop\Go\mysite\to_travel_here\TravelSpider\proxyPool\dbManager\proxyDBManager.py", line 97, in insert_proxy_table
    self.cursor.execute(insertSql, data)
  File "C:\Python\lib\site-packages\pymysql\cursors.py", line 165, in execute
    result = self._query(query)
  File "C:\Python\lib\site-packages\pymysql\cursors.py", line 321, in _query
    conn.query(q)
  File "C:\Python\lib\site-packages\pymysql\connections.py", line 860, in query
    self._affected_rows = self._read_query_result(unbuffered=unbuffered)
  File "C:\Python\lib\site-packages\pymysql\connections.py", line 1061, in _read_query_result
    result.read()
  File "C:\Python\lib\site-packages\pymysql\connections.py", line 1349, in read
    first_packet = self.connection._read_packet()
  File "C:\Python\lib\site-packages\pymysql\connections.py", line 1018, in _read_packet
    packet.check_error()
  File "C:\Python\lib\site-packages\pymysql\connections.py", line 384, in check_error
    err.raise_mysql_exception(self._data)
  File "C:\Python\lib\site-packages\pymysql\err.py", line 107, in raise_mysql_exception
    raise errorclass(errno, errval)
pymysql.err.ProgrammingError: (1146, "Table 'proxy.proxy' doesn't exist")
2018-Mar-28 18:58:55 proxyDBManager.py[line:102]/ERROR/  ===== mysql insert_proxy exception =====
 (1146, "Table 'proxy.proxy' doesn't exist")
Traceback (most recent call last):
  File "C:\Users\Cheney and Bean\Desktop\Go\mysite\to_travel_here\TravelSpider\proxyPool\dbManager\proxyDBManager.py", line 97, in insert_proxy_table
    self.cursor.execute(insertSql, data)
  File "C:\Python\lib\site-packages\pymysql\cursors.py", line 165, in execute
    result = self._query(query)
  File "C:\Python\lib\site-packages\pymysql\cursors.py", line 321, in _query
    conn.query(q)
  File "C:\Python\lib\site-packages\pymysql\connections.py", line 860, in query
    self._affected_rows = self._read_query_result(unbuffered=unbuffered)
  File "C:\Python\lib\site-packages\pymysql\connections.py", line 1061, in _read_query_result
    result.read()
  File "C:\Python\lib\site-packages\pymysql\connections.py", line 1349, in read
    first_packet = self.connection._read_packet()
  File "C:\Python\lib\site-packages\pymysql\connections.py", line 1018, in _read_packet
    packet.check_error()
  File "C:\Python\lib\site-packages\pymysql\connections.py", line 384, in check_error
    err.raise_mysql_exception(self._data)
  File "C:\Python\lib\site-packages\pymysql\err.py", line 107, in raise_mysql_exception
    raise errorclass(errno, errval)
pymysql.err.ProgrammingError: (1146, "Table 'proxy.proxy' doesn't exist")
2018-Mar-28 18:58:55 proxyDBManager.py[line:102]/ERROR/  ===== mysql insert_proxy exception =====
 (1146, "Table 'proxy.proxy' doesn't exist")
Traceback (most recent call last):
  File "C:\Users\Cheney and Bean\Desktop\Go\mysite\to_travel_here\TravelSpider\proxyPool\dbManager\proxyDBManager.py", line 97, in insert_proxy_table
    self.cursor.execute(insertSql, data)
  File "C:\Python\lib\site-packages\pymysql\cursors.py", line 165, in execute
    result = self._query(query)
  File "C:\Python\lib\site-packages\pymysql\cursors.py", line 321, in _query
    conn.query(q)
  File "C:\Python\lib\site-packages\pymysql\connections.py", line 860, in query
    self._affected_rows = self._read_query_result(unbuffered=unbuffered)
  File "C:\Python\lib\site-packages\pymysql\connections.py", line 1061, in _read_query_result
    result.read()
  File "C:\Python\lib\site-packages\pymysql\connections.py", line 1349, in read
    first_packet = self.connection._read_packet()
  File "C:\Python\lib\site-packages\pymysql\connections.py", line 1018, in _read_packet
    packet.check_error()
  File "C:\Python\lib\site-packages\pymysql\connections.py", line 384, in check_error
    err.raise_mysql_exception(self._data)
  File "C:\Python\lib\site-packages\pymysql\err.py", line 107, in raise_mysql_exception
    raise errorclass(errno, errval)
pymysql.err.ProgrammingError: (1146, "Table 'proxy.proxy' doesn't exist")
2018-Mar-28 18:58:55 proxyDBManager.py[line:102]/ERROR/  ===== mysql insert_proxy exception =====
 (1146, "Table 'proxy.proxy' doesn't exist")
Traceback (most recent call last):
  File "C:\Users\Cheney and Bean\Desktop\Go\mysite\to_travel_here\TravelSpider\proxyPool\dbManager\proxyDBManager.py", line 97, in insert_proxy_table
    self.cursor.execute(insertSql, data)
  File "C:\Python\lib\site-packages\pymysql\cursors.py", line 165, in execute
    result = self._query(query)
  File "C:\Python\lib\site-packages\pymysql\cursors.py", line 321, in _query
    conn.query(q)
  File "C:\Python\lib\site-packages\pymysql\connections.py", line 860, in query
    self._affected_rows = self._read_query_result(unbuffered=unbuffered)
  File "C:\Python\lib\site-packages\pymysql\connections.py", line 1061, in _read_query_result
    result.read()
  File "C:\Python\lib\site-packages\pymysql\connections.py", line 1349, in read
    first_packet = self.connection._read_packet()
  File "C:\Python\lib\site-packages\pymysql\connections.py", line 1018, in _read_packet
    packet.check_error()
  File "C:\Python\lib\site-packages\pymysql\connections.py", line 384, in check_error
    err.raise_mysql_exception(self._data)
  File "C:\Python\lib\site-packages\pymysql\err.py", line 107, in raise_mysql_exception
    raise errorclass(errno, errval)
pymysql.err.ProgrammingError: (1146, "Table 'proxy.proxy' doesn't exist")
2018-Mar-28 18:58:55 proxyDBManager.py[line:102]/ERROR/  ===== mysql insert_proxy exception =====
 (1146, "Table 'proxy.proxy' doesn't exist")
Traceback (most recent call last):
  File "C:\Users\Cheney and Bean\Desktop\Go\mysite\to_travel_here\TravelSpider\proxyPool\dbManager\proxyDBManager.py", line 97, in insert_proxy_table
    self.cursor.execute(insertSql, data)
  File "C:\Python\lib\site-packages\pymysql\cursors.py", line 165, in execute
    result = self._query(query)
  File "C:\Python\lib\site-packages\pymysql\cursors.py", line 321, in _query
    conn.query(q)
  File "C:\Python\lib\site-packages\pymysql\connections.py", line 860, in query
    self._affected_rows = self._read_query_result(unbuffered=unbuffered)
  File "C:\Python\lib\site-packages\pymysql\connections.py", line 1061, in _read_query_result
    result.read()
  File "C:\Python\lib\site-packages\pymysql\connections.py", line 1349, in read
    first_packet = self.connection._read_packet()
  File "C:\Python\lib\site-packages\pymysql\connections.py", line 1018, in _read_packet
    packet.check_error()
  File "C:\Python\lib\site-packages\pymysql\connections.py", line 384, in check_error
    err.raise_mysql_exception(self._data)
  File "C:\Python\lib\site-packages\pymysql\err.py", line 107, in raise_mysql_exception
    raise errorclass(errno, errval)
pymysql.err.ProgrammingError: (1146, "Table 'proxy.proxy' doesn't exist")
2018-Mar-28 18:58:55 proxyDBManager.py[line:102]/ERROR/  ===== mysql insert_proxy exception =====
 (1146, "Table 'proxy.proxy' doesn't exist")
Traceback (most recent call last):
  File "C:\Users\Cheney and Bean\Desktop\Go\mysite\to_travel_here\TravelSpider\proxyPool\dbManager\proxyDBManager.py", line 97, in insert_proxy_table
    self.cursor.execute(insertSql, data)
  File "C:\Python\lib\site-packages\pymysql\cursors.py", line 165, in execute
    result = self._query(query)
  File "C:\Python\lib\site-packages\pymysql\cursors.py", line 321, in _query
    conn.query(q)
  File "C:\Python\lib\site-packages\pymysql\connections.py", line 860, in query
    self._affected_rows = self._read_query_result(unbuffered=unbuffered)
  File "C:\Python\lib\site-packages\pymysql\connections.py", line 1061, in _read_query_result
    result.read()
  File "C:\Python\lib\site-packages\pymysql\connections.py", line 1349, in read
    first_packet = self.connection._read_packet()
  File "C:\Python\lib\site-packages\pymysql\connections.py", line 1018, in _read_packet
    packet.check_error()
  File "C:\Python\lib\site-packages\pymysql\connections.py", line 384, in check_error
    err.raise_mysql_exception(self._data)
  File "C:\Python\lib\site-packages\pymysql\err.py", line 107, in raise_mysql_exception
    raise errorclass(errno, errval)
pymysql.err.ProgrammingError: (1146, "Table 'proxy.proxy' doesn't exist")
2018-Mar-28 18:58:55 proxyDBManager.py[line:102]/ERROR/  ===== mysql insert_proxy exception =====
 (1146, "Table 'proxy.proxy' doesn't exist")
Traceback (most recent call last):
  File "C:\Users\Cheney and Bean\Desktop\Go\mysite\to_travel_here\TravelSpider\proxyPool\dbManager\proxyDBManager.py", line 97, in insert_proxy_table
    self.cursor.execute(insertSql, data)
  File "C:\Python\lib\site-packages\pymysql\cursors.py", line 165, in execute
    result = self._query(query)
  File "C:\Python\lib\site-packages\pymysql\cursors.py", line 321, in _query
    conn.query(q)
  File "C:\Python\lib\site-packages\pymysql\connections.py", line 860, in query
    self._affected_rows = self._read_query_result(unbuffered=unbuffered)
  File "C:\Python\lib\site-packages\pymysql\connections.py", line 1061, in _read_query_result
    result.read()
  File "C:\Python\lib\site-packages\pymysql\connections.py", line 1349, in read
    first_packet = self.connection._read_packet()
  File "C:\Python\lib\site-packages\pymysql\connections.py", line 1018, in _read_packet
    packet.check_error()
  File "C:\Python\lib\site-packages\pymysql\connections.py", line 384, in check_error
    err.raise_mysql_exception(self._data)
  File "C:\Python\lib\site-packages\pymysql\err.py", line 107, in raise_mysql_exception
    raise errorclass(errno, errval)
pymysql.err.ProgrammingError: (1146, "Table 'proxy.proxy' doesn't exist")
2018-Mar-28 18:58:55 proxyDBManager.py[line:102]/ERROR/  ===== mysql insert_proxy exception =====
 (1146, "Table 'proxy.proxy' doesn't exist")
Traceback (most recent call last):
  File "C:\Users\Cheney and Bean\Desktop\Go\mysite\to_travel_here\TravelSpider\proxyPool\dbManager\proxyDBManager.py", line 97, in insert_proxy_table
    self.cursor.execute(insertSql, data)
  File "C:\Python\lib\site-packages\pymysql\cursors.py", line 165, in execute
    result = self._query(query)
  File "C:\Python\lib\site-packages\pymysql\cursors.py", line 321, in _query
    conn.query(q)
  File "C:\Python\lib\site-packages\pymysql\connections.py", line 860, in query
    self._affected_rows = self._read_query_result(unbuffered=unbuffered)
  File "C:\Python\lib\site-packages\pymysql\connections.py", line 1061, in _read_query_result
    result.read()
  File "C:\Python\lib\site-packages\pymysql\connections.py", line 1349, in read
    first_packet = self.connection._read_packet()
  File "C:\Python\lib\site-packages\pymysql\connections.py", line 1018, in _read_packet
    packet.check_error()
  File "C:\Python\lib\site-packages\pymysql\connections.py", line 384, in check_error
    err.raise_mysql_exception(self._data)
  File "C:\Python\lib\site-packages\pymysql\err.py", line 107, in raise_mysql_exception
    raise errorclass(errno, errval)
pymysql.err.ProgrammingError: (1146, "Table 'proxy.proxy' doesn't exist")
2018-Mar-28 18:58:55 proxyDBManager.py[line:102]/ERROR/  ===== mysql insert_proxy exception =====
 (1146, "Table 'proxy.proxy' doesn't exist")
Traceback (most recent call last):
  File "C:\Users\Cheney and Bean\Desktop\Go\mysite\to_travel_here\TravelSpider\proxyPool\dbManager\proxyDBManager.py", line 97, in insert_proxy_table
    self.cursor.execute(insertSql, data)
  File "C:\Python\lib\site-packages\pymysql\cursors.py", line 165, in execute
    result = self._query(query)
  File "C:\Python\lib\site-packages\pymysql\cursors.py", line 321, in _query
    conn.query(q)
  File "C:\Python\lib\site-packages\pymysql\connections.py", line 860, in query
    self._affected_rows = self._read_query_result(unbuffered=unbuffered)
  File "C:\Python\lib\site-packages\pymysql\connections.py", line 1061, in _read_query_result
    result.read()
  File "C:\Python\lib\site-packages\pymysql\connections.py", line 1349, in read
    first_packet = self.connection._read_packet()
  File "C:\Python\lib\site-packages\pymysql\connections.py", line 1018, in _read_packet
    packet.check_error()
  File "C:\Python\lib\site-packages\pymysql\connections.py", line 384, in check_error
    err.raise_mysql_exception(self._data)
  File "C:\Python\lib\site-packages\pymysql\err.py", line 107, in raise_mysql_exception
    raise errorclass(errno, errval)
pymysql.err.ProgrammingError: (1146, "Table 'proxy.proxy' doesn't exist")
2018-Mar-28 18:58:55 proxyDBManager.py[line:102]/ERROR/  ===== mysql insert_proxy exception =====
 (1146, "Table 'proxy.proxy' doesn't exist")
Traceback (most recent call last):
  File "C:\Users\Cheney and Bean\Desktop\Go\mysite\to_travel_here\TravelSpider\proxyPool\dbManager\proxyDBManager.py", line 97, in insert_proxy_table
    self.cursor.execute(insertSql, data)
  File "C:\Python\lib\site-packages\pymysql\cursors.py", line 165, in execute
    result = self._query(query)
  File "C:\Python\lib\site-packages\pymysql\cursors.py", line 321, in _query
    conn.query(q)
  File "C:\Python\lib\site-packages\pymysql\connections.py", line 860, in query
    self._affected_rows = self._read_query_result(unbuffered=unbuffered)
  File "C:\Python\lib\site-packages\pymysql\connections.py", line 1061, in _read_query_result
    result.read()
  File "C:\Python\lib\site-packages\pymysql\connections.py", line 1349, in read
    first_packet = self.connection._read_packet()
  File "C:\Python\lib\site-packages\pymysql\connections.py", line 1018, in _read_packet
    packet.check_error()
  File "C:\Python\lib\site-packages\pymysql\connections.py", line 384, in check_error
    err.raise_mysql_exception(self._data)
  File "C:\Python\lib\site-packages\pymysql\err.py", line 107, in raise_mysql_exception
    raise errorclass(errno, errval)
pymysql.err.ProgrammingError: (1146, "Table 'proxy.proxy' doesn't exist")
2018-Mar-28 18:58:55 proxyDBManager.py[line:102]/ERROR/  ===== mysql insert_proxy exception =====
 (1146, "Table 'proxy.proxy' doesn't exist")
Traceback (most recent call last):
  File "C:\Users\Cheney and Bean\Desktop\Go\mysite\to_travel_here\TravelSpider\proxyPool\dbManager\proxyDBManager.py", line 97, in insert_proxy_table
    self.cursor.execute(insertSql, data)
  File "C:\Python\lib\site-packages\pymysql\cursors.py", line 165, in execute
    result = self._query(query)
  File "C:\Python\lib\site-packages\pymysql\cursors.py", line 321, in _query
    conn.query(q)
  File "C:\Python\lib\site-packages\pymysql\connections.py", line 860, in query
    self._affected_rows = self._read_query_result(unbuffered=unbuffered)
  File "C:\Python\lib\site-packages\pymysql\connections.py", line 1061, in _read_query_result
    result.read()
  File "C:\Python\lib\site-packages\pymysql\connections.py", line 1349, in read
    first_packet = self.connection._read_packet()
  File "C:\Python\lib\site-packages\pymysql\connections.py", line 1018, in _read_packet
    packet.check_error()
  File "C:\Python\lib\site-packages\pymysql\connections.py", line 384, in check_error
    err.raise_mysql_exception(self._data)
  File "C:\Python\lib\site-packages\pymysql\err.py", line 107, in raise_mysql_exception
    raise errorclass(errno, errval)
pymysql.err.ProgrammingError: (1146, "Table 'proxy.proxy' doesn't exist")
2018-Mar-28 18:58:55 proxyDBManager.py[line:102]/ERROR/  ===== mysql insert_proxy exception =====
 (1146, "Table 'proxy.proxy' doesn't exist")
Traceback (most recent call last):
  File "C:\Users\Cheney and Bean\Desktop\Go\mysite\to_travel_here\TravelSpider\proxyPool\dbManager\proxyDBManager.py", line 97, in insert_proxy_table
    self.cursor.execute(insertSql, data)
  File "C:\Python\lib\site-packages\pymysql\cursors.py", line 165, in execute
    result = self._query(query)
  File "C:\Python\lib\site-packages\pymysql\cursors.py", line 321, in _query
    conn.query(q)
  File "C:\Python\lib\site-packages\pymysql\connections.py", line 860, in query
    self._affected_rows = self._read_query_result(unbuffered=unbuffered)
  File "C:\Python\lib\site-packages\pymysql\connections.py", line 1061, in _read_query_result
    result.read()
  File "C:\Python\lib\site-packages\pymysql\connections.py", line 1349, in read
    first_packet = self.connection._read_packet()
  File "C:\Python\lib\site-packages\pymysql\connections.py", line 1018, in _read_packet
    packet.check_error()
  File "C:\Python\lib\site-packages\pymysql\connections.py", line 384, in check_error
    err.raise_mysql_exception(self._data)
  File "C:\Python\lib\site-packages\pymysql\err.py", line 107, in raise_mysql_exception
    raise errorclass(errno, errval)
pymysql.err.ProgrammingError: (1146, "Table 'proxy.proxy' doesn't exist")
2018-Mar-28 18:58:55 proxyDBManager.py[line:102]/ERROR/  ===== mysql insert_proxy exception =====
 (1146, "Table 'proxy.proxy' doesn't exist")
Traceback (most recent call last):
  File "C:\Users\Cheney and Bean\Desktop\Go\mysite\to_travel_here\TravelSpider\proxyPool\dbManager\proxyDBManager.py", line 97, in insert_proxy_table
    self.cursor.execute(insertSql, data)
  File "C:\Python\lib\site-packages\pymysql\cursors.py", line 165, in execute
    result = self._query(query)
  File "C:\Python\lib\site-packages\pymysql\cursors.py", line 321, in _query
    conn.query(q)
  File "C:\Python\lib\site-packages\pymysql\connections.py", line 860, in query
    self._affected_rows = self._read_query_result(unbuffered=unbuffered)
  File "C:\Python\lib\site-packages\pymysql\connections.py", line 1061, in _read_query_result
    result.read()
  File "C:\Python\lib\site-packages\pymysql\connections.py", line 1349, in read
    first_packet = self.connection._read_packet()
  File "C:\Python\lib\site-packages\pymysql\connections.py", line 1018, in _read_packet
    packet.check_error()
  File "C:\Python\lib\site-packages\pymysql\connections.py", line 384, in check_error
    err.raise_mysql_exception(self._data)
  File "C:\Python\lib\site-packages\pymysql\err.py", line 107, in raise_mysql_exception
    raise errorclass(errno, errval)
pymysql.err.ProgrammingError: (1146, "Table 'proxy.proxy' doesn't exist")
2018-Mar-28 18:58:58 base.py[line:433]/INFO/  Adding job tentatively -- it will be properly scheduled when the scheduler starts
2018-Mar-28 18:58:58 base.py[line:867]/INFO/  Added job "ProxyPoolWorker.__check_ip_availability_task" to job store "default"
2018-Mar-28 18:58:58 base.py[line:159]/INFO/  Scheduler started
2018-Mar-28 18:58:58 base.py[line:926]/DEBUG/  Looking for jobs to run
2018-Mar-28 18:58:58 base.py[line:1006]/DEBUG/  Next wakeup is due at 2018-03-28 19:08:58.215753+08:00 (in 599.999002 seconds)
2018-Mar-28 18:58:58 log.py[line:146]/INFO/  Scrapy 1.5.0 started (bot: TravelSpider)
2018-Mar-28 18:58:58 log.py[line:149]/INFO/  Versions: lxml 4.1.0.0, libxml2 2.9.5, cssselect 1.0.3, parsel 1.4.0, w3lib 1.19.0, Twisted 17.9.0, Python 3.6.2 (v3.6.2:5fd33b5, Jul  8 2017, 04:14:34) [MSC v.1900 32 bit (Intel)], pyOpenSSL 17.5.0 (OpenSSL 1.1.0g  2 Nov 2017), cryptography 2.2.1, Platform Windows-10-10.0.16299-SP0
